Exception in callback _task_done(<Task finishe...not defined")>) at /Users/damonguzman/Desktop/projects/turing_agents/.venv/lib/python3.12/site-packages/aio_pika/tools.py:43
handle: <Handle _task_done(<Task finishe...not defined")>) at /Users/damonguzman/Desktop/projects/turing_agents/.venv/lib/python3.12/site-packages/aio_pika/tools.py:43>
Traceback (most recent call last):
  File "/Users/damonguzman/.local/share/uv/python/cpython-3.12.11-macos-aarch64-none/lib/python3.12/asyncio/events.py", line 88, in _run
    self._context.run(self._callback, *self._args)
  File "/Users/damonguzman/Desktop/projects/turing_agents/.venv/lib/python3.12/site-packages/aio_pika/tools.py", line 47, in _task_done
    raise exc
  File "/Users/damonguzman/Desktop/projects/turing_agents/.venv/lib/python3.12/site-packages/aio_pika/tools.py", line 288, in wrapper
    return await result
           ^^^^^^^^^^^^
  File "/Users/damonguzman/Desktop/projects/turing_agents/scripts/coordinator.py", line 59, in _on_message
    token = context.attach(ctx)
            ^^^^^^^
NameError: name 'context' is not defined
Task exception was never retrieved
future: <Task finished name='Task-16' coro=<consumer() done, defined at /Users/damonguzman/Desktop/projects/turing_agents/.venv/lib/python3.12/site-packages/aio_pika/queue.py:31> exception=NameError("name 'context' is not defined")>
Traceback (most recent call last):
  File "/Users/damonguzman/Desktop/projects/turing_agents/.venv/lib/python3.12/site-packages/aio_pika/queue.py", line 37, in consumer
    return await create_task(callback, message)
           ^^^^^^^^^^^^^^^^^^^^^^^^^^^^^^^^^^^^
  File "/Users/damonguzman/Desktop/projects/turing_agents/.venv/lib/python3.12/site-packages/aio_pika/tools.py", line 288, in wrapper
    return await result
           ^^^^^^^^^^^^
  File "/Users/damonguzman/Desktop/projects/turing_agents/scripts/coordinator.py", line 59, in _on_message
    token = context.attach(ctx)
            ^^^^^^^
NameError: name 'context' is not defined
Exception in callback _task_done(<Task finishe...not defined")>) at /Users/damonguzman/Desktop/projects/turing_agents/.venv/lib/python3.12/site-packages/aio_pika/tools.py:43
handle: <Handle _task_done(<Task finishe...not defined")>) at /Users/damonguzman/Desktop/projects/turing_agents/.venv/lib/python3.12/site-packages/aio_pika/tools.py:43>
Traceback (most recent call last):
  File "/Users/damonguzman/.local/share/uv/python/cpython-3.12.11-macos-aarch64-none/lib/python3.12/asyncio/events.py", line 88, in _run
    self._context.run(self._callback, *self._args)
  File "/Users/damonguzman/Desktop/projects/turing_agents/.venv/lib/python3.12/site-packages/aio_pika/tools.py", line 47, in _task_done
    raise exc
  File "/Users/damonguzman/Desktop/projects/turing_agents/.venv/lib/python3.12/site-packages/aio_pika/tools.py", line 288, in wrapper
    return await result
           ^^^^^^^^^^^^
  File "/Users/damonguzman/Desktop/projects/turing_agents/scripts/coordinator.py", line 59, in _on_message
    token = context.attach(ctx)
            ^^^^^^^
NameError: name 'context' is not defined
Task exception was never retrieved
future: <Task finished name='Task-18' coro=<consumer() done, defined at /Users/damonguzman/Desktop/projects/turing_agents/.venv/lib/python3.12/site-packages/aio_pika/queue.py:31> exception=NameError("name 'context' is not defined")>
Traceback (most recent call last):
  File "/Users/damonguzman/Desktop/projects/turing_agents/.venv/lib/python3.12/site-packages/aio_pika/queue.py", line 37, in consumer
    return await create_task(callback, message)
           ^^^^^^^^^^^^^^^^^^^^^^^^^^^^^^^^^^^^
  File "/Users/damonguzman/Desktop/projects/turing_agents/.venv/lib/python3.12/site-packages/aio_pika/tools.py", line 288, in wrapper
    return await result
           ^^^^^^^^^^^^
  File "/Users/damonguzman/Desktop/projects/turing_agents/scripts/coordinator.py", line 59, in _on_message
    token = context.attach(ctx)
            ^^^^^^^
NameError: name 'context' is not defined
Exception in callback _task_done(<Task finishe...not defined")>) at /Users/damonguzman/Desktop/projects/turing_agents/.venv/lib/python3.12/site-packages/aio_pika/tools.py:43
handle: <Handle _task_done(<Task finishe...not defined")>) at /Users/damonguzman/Desktop/projects/turing_agents/.venv/lib/python3.12/site-packages/aio_pika/tools.py:43>
Traceback (most recent call last):
  File "/Users/damonguzman/.local/share/uv/python/cpython-3.12.11-macos-aarch64-none/lib/python3.12/asyncio/events.py", line 88, in _run
    self._context.run(self._callback, *self._args)
  File "/Users/damonguzman/Desktop/projects/turing_agents/.venv/lib/python3.12/site-packages/aio_pika/tools.py", line 47, in _task_done
    raise exc
  File "/Users/damonguzman/Desktop/projects/turing_agents/.venv/lib/python3.12/site-packages/aio_pika/tools.py", line 288, in wrapper
    return await result
           ^^^^^^^^^^^^
  File "/Users/damonguzman/Desktop/projects/turing_agents/scripts/coordinator.py", line 59, in _on_message
    token = context.attach(ctx)
            ^^^^^^^
NameError: name 'context' is not defined
Task exception was never retrieved
future: <Task finished name='Task-20' coro=<consumer() done, defined at /Users/damonguzman/Desktop/projects/turing_agents/.venv/lib/python3.12/site-packages/aio_pika/queue.py:31> exception=NameError("name 'context' is not defined")>
Traceback (most recent call last):
  File "/Users/damonguzman/Desktop/projects/turing_agents/.venv/lib/python3.12/site-packages/aio_pika/queue.py", line 37, in consumer
    return await create_task(callback, message)
           ^^^^^^^^^^^^^^^^^^^^^^^^^^^^^^^^^^^^
  File "/Users/damonguzman/Desktop/projects/turing_agents/.venv/lib/python3.12/site-packages/aio_pika/tools.py", line 288, in wrapper
    return await result
           ^^^^^^^^^^^^
  File "/Users/damonguzman/Desktop/projects/turing_agents/scripts/coordinator.py", line 59, in _on_message
    token = context.attach(ctx)
            ^^^^^^^
NameError: name 'context' is not defined
Exception in callback _task_done(<Task finishe...not defined")>) at /Users/damonguzman/Desktop/projects/turing_agents/.venv/lib/python3.12/site-packages/aio_pika/tools.py:43
handle: <Handle _task_done(<Task finishe...not defined")>) at /Users/damonguzman/Desktop/projects/turing_agents/.venv/lib/python3.12/site-packages/aio_pika/tools.py:43>
Traceback (most recent call last):
  File "/Users/damonguzman/.local/share/uv/python/cpython-3.12.11-macos-aarch64-none/lib/python3.12/asyncio/events.py", line 88, in _run
    self._context.run(self._callback, *self._args)
  File "/Users/damonguzman/Desktop/projects/turing_agents/.venv/lib/python3.12/site-packages/aio_pika/tools.py", line 47, in _task_done
    raise exc
  File "/Users/damonguzman/Desktop/projects/turing_agents/.venv/lib/python3.12/site-packages/aio_pika/tools.py", line 288, in wrapper
    return await result
           ^^^^^^^^^^^^
  File "/Users/damonguzman/Desktop/projects/turing_agents/scripts/coordinator.py", line 59, in _on_message
    token = context.attach(ctx)
            ^^^^^^^
NameError: name 'context' is not defined
Task exception was never retrieved
future: <Task finished name='Task-22' coro=<consumer() done, defined at /Users/damonguzman/Desktop/projects/turing_agents/.venv/lib/python3.12/site-packages/aio_pika/queue.py:31> exception=NameError("name 'context' is not defined")>
Traceback (most recent call last):
  File "/Users/damonguzman/Desktop/projects/turing_agents/.venv/lib/python3.12/site-packages/aio_pika/queue.py", line 37, in consumer
    return await create_task(callback, message)
           ^^^^^^^^^^^^^^^^^^^^^^^^^^^^^^^^^^^^
  File "/Users/damonguzman/Desktop/projects/turing_agents/.venv/lib/python3.12/site-packages/aio_pika/tools.py", line 288, in wrapper
    return await result
           ^^^^^^^^^^^^
  File "/Users/damonguzman/Desktop/projects/turing_agents/scripts/coordinator.py", line 59, in _on_message
    token = context.attach(ctx)
            ^^^^^^^
NameError: name 'context' is not defined
Exception in callback _task_done(<Task finishe...not defined")>) at /Users/damonguzman/Desktop/projects/turing_agents/.venv/lib/python3.12/site-packages/aio_pika/tools.py:43
handle: <Handle _task_done(<Task finishe...not defined")>) at /Users/damonguzman/Desktop/projects/turing_agents/.venv/lib/python3.12/site-packages/aio_pika/tools.py:43>
Traceback (most recent call last):
  File "/Users/damonguzman/.local/share/uv/python/cpython-3.12.11-macos-aarch64-none/lib/python3.12/asyncio/events.py", line 88, in _run
    self._context.run(self._callback, *self._args)
  File "/Users/damonguzman/Desktop/projects/turing_agents/.venv/lib/python3.12/site-packages/aio_pika/tools.py", line 47, in _task_done
    raise exc
  File "/Users/damonguzman/Desktop/projects/turing_agents/.venv/lib/python3.12/site-packages/aio_pika/tools.py", line 288, in wrapper
    return await result
           ^^^^^^^^^^^^
  File "/Users/damonguzman/Desktop/projects/turing_agents/scripts/coordinator.py", line 59, in _on_message
    token = context.attach(ctx)
            ^^^^^^^
NameError: name 'context' is not defined
Task exception was never retrieved
future: <Task finished name='Task-24' coro=<consumer() done, defined at /Users/damonguzman/Desktop/projects/turing_agents/.venv/lib/python3.12/site-packages/aio_pika/queue.py:31> exception=NameError("name 'context' is not defined")>
Traceback (most recent call last):
  File "/Users/damonguzman/Desktop/projects/turing_agents/.venv/lib/python3.12/site-packages/aio_pika/queue.py", line 37, in consumer
    return await create_task(callback, message)
           ^^^^^^^^^^^^^^^^^^^^^^^^^^^^^^^^^^^^
  File "/Users/damonguzman/Desktop/projects/turing_agents/.venv/lib/python3.12/site-packages/aio_pika/tools.py", line 288, in wrapper
    return await result
           ^^^^^^^^^^^^
  File "/Users/damonguzman/Desktop/projects/turing_agents/scripts/coordinator.py", line 59, in _on_message
    token = context.attach(ctx)
            ^^^^^^^
NameError: name 'context' is not defined
Exception in callback _task_done(<Task finishe...not defined")>) at /Users/damonguzman/Desktop/projects/turing_agents/.venv/lib/python3.12/site-packages/aio_pika/tools.py:43
handle: <Handle _task_done(<Task finishe...not defined")>) at /Users/damonguzman/Desktop/projects/turing_agents/.venv/lib/python3.12/site-packages/aio_pika/tools.py:43>
Traceback (most recent call last):
  File "/Users/damonguzman/.local/share/uv/python/cpython-3.12.11-macos-aarch64-none/lib/python3.12/asyncio/events.py", line 88, in _run
    self._context.run(self._callback, *self._args)
  File "/Users/damonguzman/Desktop/projects/turing_agents/.venv/lib/python3.12/site-packages/aio_pika/tools.py", line 47, in _task_done
    raise exc
  File "/Users/damonguzman/Desktop/projects/turing_agents/.venv/lib/python3.12/site-packages/aio_pika/tools.py", line 288, in wrapper
    return await result
           ^^^^^^^^^^^^
  File "/Users/damonguzman/Desktop/projects/turing_agents/scripts/coordinator.py", line 59, in _on_message
    token = context.attach(ctx)
            ^^^^^^^
NameError: name 'context' is not defined
Task exception was never retrieved
future: <Task finished name='Task-26' coro=<consumer() done, defined at /Users/damonguzman/Desktop/projects/turing_agents/.venv/lib/python3.12/site-packages/aio_pika/queue.py:31> exception=NameError("name 'context' is not defined")>
Traceback (most recent call last):
  File "/Users/damonguzman/Desktop/projects/turing_agents/.venv/lib/python3.12/site-packages/aio_pika/queue.py", line 37, in consumer
    return await create_task(callback, message)
           ^^^^^^^^^^^^^^^^^^^^^^^^^^^^^^^^^^^^
  File "/Users/damonguzman/Desktop/projects/turing_agents/.venv/lib/python3.12/site-packages/aio_pika/tools.py", line 288, in wrapper
    return await result
           ^^^^^^^^^^^^
  File "/Users/damonguzman/Desktop/projects/turing_agents/scripts/coordinator.py", line 59, in _on_message
    token = context.attach(ctx)
            ^^^^^^^
NameError: name 'context' is not defined
Exception in callback _task_done(<Task finishe...not defined")>) at /Users/damonguzman/Desktop/projects/turing_agents/.venv/lib/python3.12/site-packages/aio_pika/tools.py:43
handle: <Handle _task_done(<Task finishe...not defined")>) at /Users/damonguzman/Desktop/projects/turing_agents/.venv/lib/python3.12/site-packages/aio_pika/tools.py:43>
Traceback (most recent call last):
  File "/Users/damonguzman/.local/share/uv/python/cpython-3.12.11-macos-aarch64-none/lib/python3.12/asyncio/events.py", line 88, in _run
    self._context.run(self._callback, *self._args)
  File "/Users/damonguzman/Desktop/projects/turing_agents/.venv/lib/python3.12/site-packages/aio_pika/tools.py", line 47, in _task_done
    raise exc
  File "/Users/damonguzman/Desktop/projects/turing_agents/.venv/lib/python3.12/site-packages/aio_pika/tools.py", line 288, in wrapper
    return await result
           ^^^^^^^^^^^^
  File "/Users/damonguzman/Desktop/projects/turing_agents/scripts/coordinator.py", line 59, in _on_message
    token = context.attach(ctx)
            ^^^^^^^
NameError: name 'context' is not defined
Task exception was never retrieved
future: <Task finished name='Task-28' coro=<consumer() done, defined at /Users/damonguzman/Desktop/projects/turing_agents/.venv/lib/python3.12/site-packages/aio_pika/queue.py:31> exception=NameError("name 'context' is not defined")>
Traceback (most recent call last):
  File "/Users/damonguzman/Desktop/projects/turing_agents/.venv/lib/python3.12/site-packages/aio_pika/queue.py", line 37, in consumer
    return await create_task(callback, message)
           ^^^^^^^^^^^^^^^^^^^^^^^^^^^^^^^^^^^^
  File "/Users/damonguzman/Desktop/projects/turing_agents/.venv/lib/python3.12/site-packages/aio_pika/tools.py", line 288, in wrapper
    return await result
           ^^^^^^^^^^^^
  File "/Users/damonguzman/Desktop/projects/turing_agents/scripts/coordinator.py", line 59, in _on_message
    token = context.attach(ctx)
            ^^^^^^^
NameError: name 'context' is not defined
Exception in callback _task_done(<Task finishe...not defined")>) at /Users/damonguzman/Desktop/projects/turing_agents/.venv/lib/python3.12/site-packages/aio_pika/tools.py:43
handle: <Handle _task_done(<Task finishe...not defined")>) at /Users/damonguzman/Desktop/projects/turing_agents/.venv/lib/python3.12/site-packages/aio_pika/tools.py:43>
Traceback (most recent call last):
  File "/Users/damonguzman/.local/share/uv/python/cpython-3.12.11-macos-aarch64-none/lib/python3.12/asyncio/events.py", line 88, in _run
    self._context.run(self._callback, *self._args)
  File "/Users/damonguzman/Desktop/projects/turing_agents/.venv/lib/python3.12/site-packages/aio_pika/tools.py", line 47, in _task_done
    raise exc
  File "/Users/damonguzman/Desktop/projects/turing_agents/.venv/lib/python3.12/site-packages/aio_pika/tools.py", line 288, in wrapper
    return await result
           ^^^^^^^^^^^^
  File "/Users/damonguzman/Desktop/projects/turing_agents/scripts/coordinator.py", line 59, in _on_message
    token = context.attach(ctx)
            ^^^^^^^
NameError: name 'context' is not defined
Task exception was never retrieved
future: <Task finished name='Task-30' coro=<consumer() done, defined at /Users/damonguzman/Desktop/projects/turing_agents/.venv/lib/python3.12/site-packages/aio_pika/queue.py:31> exception=NameError("name 'context' is not defined")>
Traceback (most recent call last):
  File "/Users/damonguzman/Desktop/projects/turing_agents/.venv/lib/python3.12/site-packages/aio_pika/queue.py", line 37, in consumer
    return await create_task(callback, message)
           ^^^^^^^^^^^^^^^^^^^^^^^^^^^^^^^^^^^^
  File "/Users/damonguzman/Desktop/projects/turing_agents/.venv/lib/python3.12/site-packages/aio_pika/tools.py", line 288, in wrapper
    return await result
           ^^^^^^^^^^^^
  File "/Users/damonguzman/Desktop/projects/turing_agents/scripts/coordinator.py", line 59, in _on_message
    token = context.attach(ctx)
            ^^^^^^^
NameError: name 'context' is not defined
Exception in callback _task_done(<Task finishe...not defined")>) at /Users/damonguzman/Desktop/projects/turing_agents/.venv/lib/python3.12/site-packages/aio_pika/tools.py:43
handle: <Handle _task_done(<Task finishe...not defined")>) at /Users/damonguzman/Desktop/projects/turing_agents/.venv/lib/python3.12/site-packages/aio_pika/tools.py:43>
Traceback (most recent call last):
  File "/Users/damonguzman/.local/share/uv/python/cpython-3.12.11-macos-aarch64-none/lib/python3.12/asyncio/events.py", line 88, in _run
    self._context.run(self._callback, *self._args)
  File "/Users/damonguzman/Desktop/projects/turing_agents/.venv/lib/python3.12/site-packages/aio_pika/tools.py", line 47, in _task_done
    raise exc
  File "/Users/damonguzman/Desktop/projects/turing_agents/.venv/lib/python3.12/site-packages/aio_pika/tools.py", line 288, in wrapper
    return await result
           ^^^^^^^^^^^^
  File "/Users/damonguzman/Desktop/projects/turing_agents/scripts/coordinator.py", line 59, in _on_message
    token = context.attach(ctx)
            ^^^^^^^
NameError: name 'context' is not defined
Task exception was never retrieved
future: <Task finished name='Task-32' coro=<consumer() done, defined at /Users/damonguzman/Desktop/projects/turing_agents/.venv/lib/python3.12/site-packages/aio_pika/queue.py:31> exception=NameError("name 'context' is not defined")>
Traceback (most recent call last):
  File "/Users/damonguzman/Desktop/projects/turing_agents/.venv/lib/python3.12/site-packages/aio_pika/queue.py", line 37, in consumer
    return await create_task(callback, message)
           ^^^^^^^^^^^^^^^^^^^^^^^^^^^^^^^^^^^^
  File "/Users/damonguzman/Desktop/projects/turing_agents/.venv/lib/python3.12/site-packages/aio_pika/tools.py", line 288, in wrapper
    return await result
           ^^^^^^^^^^^^
  File "/Users/damonguzman/Desktop/projects/turing_agents/scripts/coordinator.py", line 59, in _on_message
    token = context.attach(ctx)
            ^^^^^^^
NameError: name 'context' is not defined
Exception in callback _task_done(<Task finishe...not defined")>) at /Users/damonguzman/Desktop/projects/turing_agents/.venv/lib/python3.12/site-packages/aio_pika/tools.py:43
handle: <Handle _task_done(<Task finishe...not defined")>) at /Users/damonguzman/Desktop/projects/turing_agents/.venv/lib/python3.12/site-packages/aio_pika/tools.py:43>
Traceback (most recent call last):
  File "/Users/damonguzman/.local/share/uv/python/cpython-3.12.11-macos-aarch64-none/lib/python3.12/asyncio/events.py", line 88, in _run
    self._context.run(self._callback, *self._args)
  File "/Users/damonguzman/Desktop/projects/turing_agents/.venv/lib/python3.12/site-packages/aio_pika/tools.py", line 47, in _task_done
    raise exc
  File "/Users/damonguzman/Desktop/projects/turing_agents/.venv/lib/python3.12/site-packages/aio_pika/tools.py", line 288, in wrapper
    return await result
           ^^^^^^^^^^^^
  File "/Users/damonguzman/Desktop/projects/turing_agents/scripts/coordinator.py", line 59, in _on_message
    token = context.attach(ctx)
            ^^^^^^^
NameError: name 'context' is not defined
Task exception was never retrieved
future: <Task finished name='Task-34' coro=<consumer() done, defined at /Users/damonguzman/Desktop/projects/turing_agents/.venv/lib/python3.12/site-packages/aio_pika/queue.py:31> exception=NameError("name 'context' is not defined")>
Traceback (most recent call last):
  File "/Users/damonguzman/Desktop/projects/turing_agents/.venv/lib/python3.12/site-packages/aio_pika/queue.py", line 37, in consumer
    return await create_task(callback, message)
           ^^^^^^^^^^^^^^^^^^^^^^^^^^^^^^^^^^^^
  File "/Users/damonguzman/Desktop/projects/turing_agents/.venv/lib/python3.12/site-packages/aio_pika/tools.py", line 288, in wrapper
    return await result
           ^^^^^^^^^^^^
  File "/Users/damonguzman/Desktop/projects/turing_agents/scripts/coordinator.py", line 59, in _on_message
    token = context.attach(ctx)
            ^^^^^^^
NameError: name 'context' is not defined
Exception in callback _task_done(<Task finishe...not defined")>) at /Users/damonguzman/Desktop/projects/turing_agents/.venv/lib/python3.12/site-packages/aio_pika/tools.py:43
handle: <Handle _task_done(<Task finishe...not defined")>) at /Users/damonguzman/Desktop/projects/turing_agents/.venv/lib/python3.12/site-packages/aio_pika/tools.py:43>
Traceback (most recent call last):
  File "/Users/damonguzman/.local/share/uv/python/cpython-3.12.11-macos-aarch64-none/lib/python3.12/asyncio/events.py", line 88, in _run
    self._context.run(self._callback, *self._args)
  File "/Users/damonguzman/Desktop/projects/turing_agents/.venv/lib/python3.12/site-packages/aio_pika/tools.py", line 47, in _task_done
    raise exc
  File "/Users/damonguzman/Desktop/projects/turing_agents/.venv/lib/python3.12/site-packages/aio_pika/tools.py", line 288, in wrapper
    return await result
           ^^^^^^^^^^^^
  File "/Users/damonguzman/Desktop/projects/turing_agents/scripts/coordinator.py", line 59, in _on_message
    token = context.attach(ctx)
            ^^^^^^^
NameError: name 'context' is not defined
Task exception was never retrieved
future: <Task finished name='Task-36' coro=<consumer() done, defined at /Users/damonguzman/Desktop/projects/turing_agents/.venv/lib/python3.12/site-packages/aio_pika/queue.py:31> exception=NameError("name 'context' is not defined")>
Traceback (most recent call last):
  File "/Users/damonguzman/Desktop/projects/turing_agents/.venv/lib/python3.12/site-packages/aio_pika/queue.py", line 37, in consumer
    return await create_task(callback, message)
           ^^^^^^^^^^^^^^^^^^^^^^^^^^^^^^^^^^^^
  File "/Users/damonguzman/Desktop/projects/turing_agents/.venv/lib/python3.12/site-packages/aio_pika/tools.py", line 288, in wrapper
    return await result
           ^^^^^^^^^^^^
  File "/Users/damonguzman/Desktop/projects/turing_agents/scripts/coordinator.py", line 59, in _on_message
    token = context.attach(ctx)
            ^^^^^^^
NameError: name 'context' is not defined
Exception in callback _task_done(<Task finishe...not defined")>) at /Users/damonguzman/Desktop/projects/turing_agents/.venv/lib/python3.12/site-packages/aio_pika/tools.py:43
handle: <Handle _task_done(<Task finishe...not defined")>) at /Users/damonguzman/Desktop/projects/turing_agents/.venv/lib/python3.12/site-packages/aio_pika/tools.py:43>
Traceback (most recent call last):
  File "/Users/damonguzman/.local/share/uv/python/cpython-3.12.11-macos-aarch64-none/lib/python3.12/asyncio/events.py", line 88, in _run
    self._context.run(self._callback, *self._args)
  File "/Users/damonguzman/Desktop/projects/turing_agents/.venv/lib/python3.12/site-packages/aio_pika/tools.py", line 47, in _task_done
    raise exc
  File "/Users/damonguzman/Desktop/projects/turing_agents/.venv/lib/python3.12/site-packages/aio_pika/tools.py", line 288, in wrapper
    return await result
           ^^^^^^^^^^^^
  File "/Users/damonguzman/Desktop/projects/turing_agents/scripts/coordinator.py", line 59, in _on_message
    token = context.attach(ctx)
            ^^^^^^^
NameError: name 'context' is not defined
Task exception was never retrieved
future: <Task finished name='Task-38' coro=<consumer() done, defined at /Users/damonguzman/Desktop/projects/turing_agents/.venv/lib/python3.12/site-packages/aio_pika/queue.py:31> exception=NameError("name 'context' is not defined")>
Traceback (most recent call last):
  File "/Users/damonguzman/Desktop/projects/turing_agents/.venv/lib/python3.12/site-packages/aio_pika/queue.py", line 37, in consumer
    return await create_task(callback, message)
           ^^^^^^^^^^^^^^^^^^^^^^^^^^^^^^^^^^^^
  File "/Users/damonguzman/Desktop/projects/turing_agents/.venv/lib/python3.12/site-packages/aio_pika/tools.py", line 288, in wrapper
    return await result
           ^^^^^^^^^^^^
  File "/Users/damonguzman/Desktop/projects/turing_agents/scripts/coordinator.py", line 59, in _on_message
    token = context.attach(ctx)
            ^^^^^^^
NameError: name 'context' is not defined
Exception in callback _task_done(<Task finishe...not defined")>) at /Users/damonguzman/Desktop/projects/turing_agents/.venv/lib/python3.12/site-packages/aio_pika/tools.py:43
handle: <Handle _task_done(<Task finishe...not defined")>) at /Users/damonguzman/Desktop/projects/turing_agents/.venv/lib/python3.12/site-packages/aio_pika/tools.py:43>
Traceback (most recent call last):
  File "/Users/damonguzman/.local/share/uv/python/cpython-3.12.11-macos-aarch64-none/lib/python3.12/asyncio/events.py", line 88, in _run
    self._context.run(self._callback, *self._args)
  File "/Users/damonguzman/Desktop/projects/turing_agents/.venv/lib/python3.12/site-packages/aio_pika/tools.py", line 47, in _task_done
    raise exc
  File "/Users/damonguzman/Desktop/projects/turing_agents/.venv/lib/python3.12/site-packages/aio_pika/tools.py", line 288, in wrapper
    return await result
           ^^^^^^^^^^^^
  File "/Users/damonguzman/Desktop/projects/turing_agents/scripts/coordinator.py", line 59, in _on_message
    token = context.attach(ctx)
            ^^^^^^^
NameError: name 'context' is not defined
Task exception was never retrieved
future: <Task finished name='Task-40' coro=<consumer() done, defined at /Users/damonguzman/Desktop/projects/turing_agents/.venv/lib/python3.12/site-packages/aio_pika/queue.py:31> exception=NameError("name 'context' is not defined")>
Traceback (most recent call last):
  File "/Users/damonguzman/Desktop/projects/turing_agents/.venv/lib/python3.12/site-packages/aio_pika/queue.py", line 37, in consumer
    return await create_task(callback, message)
           ^^^^^^^^^^^^^^^^^^^^^^^^^^^^^^^^^^^^
  File "/Users/damonguzman/Desktop/projects/turing_agents/.venv/lib/python3.12/site-packages/aio_pika/tools.py", line 288, in wrapper
    return await result
           ^^^^^^^^^^^^
  File "/Users/damonguzman/Desktop/projects/turing_agents/scripts/coordinator.py", line 59, in _on_message
    token = context.attach(ctx)
            ^^^^^^^
NameError: name 'context' is not defined
Exception in callback _task_done(<Task finishe...not defined")>) at /Users/damonguzman/Desktop/projects/turing_agents/.venv/lib/python3.12/site-packages/aio_pika/tools.py:43
handle: <Handle _task_done(<Task finishe...not defined")>) at /Users/damonguzman/Desktop/projects/turing_agents/.venv/lib/python3.12/site-packages/aio_pika/tools.py:43>
Traceback (most recent call last):
  File "/Users/damonguzman/.local/share/uv/python/cpython-3.12.11-macos-aarch64-none/lib/python3.12/asyncio/events.py", line 88, in _run
    self._context.run(self._callback, *self._args)
  File "/Users/damonguzman/Desktop/projects/turing_agents/.venv/lib/python3.12/site-packages/aio_pika/tools.py", line 47, in _task_done
    raise exc
  File "/Users/damonguzman/Desktop/projects/turing_agents/.venv/lib/python3.12/site-packages/aio_pika/tools.py", line 288, in wrapper
    return await result
           ^^^^^^^^^^^^
  File "/Users/damonguzman/Desktop/projects/turing_agents/scripts/coordinator.py", line 59, in _on_message
    token = context.attach(ctx)
            ^^^^^^^
NameError: name 'context' is not defined
Task exception was never retrieved
future: <Task finished name='Task-42' coro=<consumer() done, defined at /Users/damonguzman/Desktop/projects/turing_agents/.venv/lib/python3.12/site-packages/aio_pika/queue.py:31> exception=NameError("name 'context' is not defined")>
Traceback (most recent call last):
  File "/Users/damonguzman/Desktop/projects/turing_agents/.venv/lib/python3.12/site-packages/aio_pika/queue.py", line 37, in consumer
    return await create_task(callback, message)
           ^^^^^^^^^^^^^^^^^^^^^^^^^^^^^^^^^^^^
  File "/Users/damonguzman/Desktop/projects/turing_agents/.venv/lib/python3.12/site-packages/aio_pika/tools.py", line 288, in wrapper
    return await result
           ^^^^^^^^^^^^
  File "/Users/damonguzman/Desktop/projects/turing_agents/scripts/coordinator.py", line 59, in _on_message
    token = context.attach(ctx)
            ^^^^^^^
NameError: name 'context' is not defined
Exception in callback _task_done(<Task finishe...not defined")>) at /Users/damonguzman/Desktop/projects/turing_agents/.venv/lib/python3.12/site-packages/aio_pika/tools.py:43
handle: <Handle _task_done(<Task finishe...not defined")>) at /Users/damonguzman/Desktop/projects/turing_agents/.venv/lib/python3.12/site-packages/aio_pika/tools.py:43>
Traceback (most recent call last):
  File "/Users/damonguzman/.local/share/uv/python/cpython-3.12.11-macos-aarch64-none/lib/python3.12/asyncio/events.py", line 88, in _run
    self._context.run(self._callback, *self._args)
  File "/Users/damonguzman/Desktop/projects/turing_agents/.venv/lib/python3.12/site-packages/aio_pika/tools.py", line 47, in _task_done
    raise exc
  File "/Users/damonguzman/Desktop/projects/turing_agents/.venv/lib/python3.12/site-packages/aio_pika/tools.py", line 288, in wrapper
    return await result
           ^^^^^^^^^^^^
  File "/Users/damonguzman/Desktop/projects/turing_agents/scripts/coordinator.py", line 59, in _on_message
    token = context.attach(ctx)
            ^^^^^^^
NameError: name 'context' is not defined
Task exception was never retrieved
future: <Task finished name='Task-44' coro=<consumer() done, defined at /Users/damonguzman/Desktop/projects/turing_agents/.venv/lib/python3.12/site-packages/aio_pika/queue.py:31> exception=NameError("name 'context' is not defined")>
Traceback (most recent call last):
  File "/Users/damonguzman/Desktop/projects/turing_agents/.venv/lib/python3.12/site-packages/aio_pika/queue.py", line 37, in consumer
    return await create_task(callback, message)
           ^^^^^^^^^^^^^^^^^^^^^^^^^^^^^^^^^^^^
  File "/Users/damonguzman/Desktop/projects/turing_agents/.venv/lib/python3.12/site-packages/aio_pika/tools.py", line 288, in wrapper
    return await result
           ^^^^^^^^^^^^
  File "/Users/damonguzman/Desktop/projects/turing_agents/scripts/coordinator.py", line 59, in _on_message
    token = context.attach(ctx)
            ^^^^^^^
NameError: name 'context' is not defined
Exception in callback _task_done(<Task finishe...not defined")>) at /Users/damonguzman/Desktop/projects/turing_agents/.venv/lib/python3.12/site-packages/aio_pika/tools.py:43
handle: <Handle _task_done(<Task finishe...not defined")>) at /Users/damonguzman/Desktop/projects/turing_agents/.venv/lib/python3.12/site-packages/aio_pika/tools.py:43>
Traceback (most recent call last):
  File "/Users/damonguzman/.local/share/uv/python/cpython-3.12.11-macos-aarch64-none/lib/python3.12/asyncio/events.py", line 88, in _run
    self._context.run(self._callback, *self._args)
  File "/Users/damonguzman/Desktop/projects/turing_agents/.venv/lib/python3.12/site-packages/aio_pika/tools.py", line 47, in _task_done
    raise exc
  File "/Users/damonguzman/Desktop/projects/turing_agents/.venv/lib/python3.12/site-packages/aio_pika/tools.py", line 288, in wrapper
    return await result
           ^^^^^^^^^^^^
  File "/Users/damonguzman/Desktop/projects/turing_agents/scripts/coordinator.py", line 59, in _on_message
    token = context.attach(ctx)
            ^^^^^^^
NameError: name 'context' is not defined
Task exception was never retrieved
future: <Task finished name='Task-46' coro=<consumer() done, defined at /Users/damonguzman/Desktop/projects/turing_agents/.venv/lib/python3.12/site-packages/aio_pika/queue.py:31> exception=NameError("name 'context' is not defined")>
Traceback (most recent call last):
  File "/Users/damonguzman/Desktop/projects/turing_agents/.venv/lib/python3.12/site-packages/aio_pika/queue.py", line 37, in consumer
    return await create_task(callback, message)
           ^^^^^^^^^^^^^^^^^^^^^^^^^^^^^^^^^^^^
  File "/Users/damonguzman/Desktop/projects/turing_agents/.venv/lib/python3.12/site-packages/aio_pika/tools.py", line 288, in wrapper
    return await result
           ^^^^^^^^^^^^
  File "/Users/damonguzman/Desktop/projects/turing_agents/scripts/coordinator.py", line 59, in _on_message
    token = context.attach(ctx)
            ^^^^^^^
NameError: name 'context' is not defined
Exception in callback _task_done(<Task finishe...not defined")>) at /Users/damonguzman/Desktop/projects/turing_agents/.venv/lib/python3.12/site-packages/aio_pika/tools.py:43
handle: <Handle _task_done(<Task finishe...not defined")>) at /Users/damonguzman/Desktop/projects/turing_agents/.venv/lib/python3.12/site-packages/aio_pika/tools.py:43>
Traceback (most recent call last):
  File "/Users/damonguzman/.local/share/uv/python/cpython-3.12.11-macos-aarch64-none/lib/python3.12/asyncio/events.py", line 88, in _run
    self._context.run(self._callback, *self._args)
  File "/Users/damonguzman/Desktop/projects/turing_agents/.venv/lib/python3.12/site-packages/aio_pika/tools.py", line 47, in _task_done
    raise exc
  File "/Users/damonguzman/Desktop/projects/turing_agents/.venv/lib/python3.12/site-packages/aio_pika/tools.py", line 288, in wrapper
    return await result
           ^^^^^^^^^^^^
  File "/Users/damonguzman/Desktop/projects/turing_agents/scripts/coordinator.py", line 59, in _on_message
    token = context.attach(ctx)
            ^^^^^^^
NameError: name 'context' is not defined
Task exception was never retrieved
future: <Task finished name='Task-48' coro=<consumer() done, defined at /Users/damonguzman/Desktop/projects/turing_agents/.venv/lib/python3.12/site-packages/aio_pika/queue.py:31> exception=NameError("name 'context' is not defined")>
Traceback (most recent call last):
  File "/Users/damonguzman/Desktop/projects/turing_agents/.venv/lib/python3.12/site-packages/aio_pika/queue.py", line 37, in consumer
    return await create_task(callback, message)
           ^^^^^^^^^^^^^^^^^^^^^^^^^^^^^^^^^^^^
  File "/Users/damonguzman/Desktop/projects/turing_agents/.venv/lib/python3.12/site-packages/aio_pika/tools.py", line 288, in wrapper
    return await result
           ^^^^^^^^^^^^
  File "/Users/damonguzman/Desktop/projects/turing_agents/scripts/coordinator.py", line 59, in _on_message
    token = context.attach(ctx)
            ^^^^^^^
NameError: name 'context' is not defined
Exception in callback _task_done(<Task finishe...not defined")>) at /Users/damonguzman/Desktop/projects/turing_agents/.venv/lib/python3.12/site-packages/aio_pika/tools.py:43
handle: <Handle _task_done(<Task finishe...not defined")>) at /Users/damonguzman/Desktop/projects/turing_agents/.venv/lib/python3.12/site-packages/aio_pika/tools.py:43>
Traceback (most recent call last):
  File "/Users/damonguzman/.local/share/uv/python/cpython-3.12.11-macos-aarch64-none/lib/python3.12/asyncio/events.py", line 88, in _run
    self._context.run(self._callback, *self._args)
  File "/Users/damonguzman/Desktop/projects/turing_agents/.venv/lib/python3.12/site-packages/aio_pika/tools.py", line 47, in _task_done
    raise exc
  File "/Users/damonguzman/Desktop/projects/turing_agents/.venv/lib/python3.12/site-packages/aio_pika/tools.py", line 288, in wrapper
    return await result
           ^^^^^^^^^^^^
  File "/Users/damonguzman/Desktop/projects/turing_agents/scripts/coordinator.py", line 59, in _on_message
    token = context.attach(ctx)
            ^^^^^^^
NameError: name 'context' is not defined
Task exception was never retrieved
future: <Task finished name='Task-50' coro=<consumer() done, defined at /Users/damonguzman/Desktop/projects/turing_agents/.venv/lib/python3.12/site-packages/aio_pika/queue.py:31> exception=NameError("name 'context' is not defined")>
Traceback (most recent call last):
  File "/Users/damonguzman/Desktop/projects/turing_agents/.venv/lib/python3.12/site-packages/aio_pika/queue.py", line 37, in consumer
    return await create_task(callback, message)
           ^^^^^^^^^^^^^^^^^^^^^^^^^^^^^^^^^^^^
  File "/Users/damonguzman/Desktop/projects/turing_agents/.venv/lib/python3.12/site-packages/aio_pika/tools.py", line 288, in wrapper
    return await result
           ^^^^^^^^^^^^
  File "/Users/damonguzman/Desktop/projects/turing_agents/scripts/coordinator.py", line 59, in _on_message
    token = context.attach(ctx)
            ^^^^^^^
NameError: name 'context' is not defined
Exception in callback _task_done(<Task finishe...not defined")>) at /Users/damonguzman/Desktop/projects/turing_agents/.venv/lib/python3.12/site-packages/aio_pika/tools.py:43
handle: <Handle _task_done(<Task finishe...not defined")>) at /Users/damonguzman/Desktop/projects/turing_agents/.venv/lib/python3.12/site-packages/aio_pika/tools.py:43>
Traceback (most recent call last):
  File "/Users/damonguzman/.local/share/uv/python/cpython-3.12.11-macos-aarch64-none/lib/python3.12/asyncio/events.py", line 88, in _run
    self._context.run(self._callback, *self._args)
  File "/Users/damonguzman/Desktop/projects/turing_agents/.venv/lib/python3.12/site-packages/aio_pika/tools.py", line 47, in _task_done
    raise exc
  File "/Users/damonguzman/Desktop/projects/turing_agents/.venv/lib/python3.12/site-packages/aio_pika/tools.py", line 288, in wrapper
    return await result
           ^^^^^^^^^^^^
  File "/Users/damonguzman/Desktop/projects/turing_agents/scripts/coordinator.py", line 59, in _on_message
    token = context.attach(ctx)
            ^^^^^^^
NameError: name 'context' is not defined
Task exception was never retrieved
future: <Task finished name='Task-52' coro=<consumer() done, defined at /Users/damonguzman/Desktop/projects/turing_agents/.venv/lib/python3.12/site-packages/aio_pika/queue.py:31> exception=NameError("name 'context' is not defined")>
Traceback (most recent call last):
  File "/Users/damonguzman/Desktop/projects/turing_agents/.venv/lib/python3.12/site-packages/aio_pika/queue.py", line 37, in consumer
    return await create_task(callback, message)
           ^^^^^^^^^^^^^^^^^^^^^^^^^^^^^^^^^^^^
  File "/Users/damonguzman/Desktop/projects/turing_agents/.venv/lib/python3.12/site-packages/aio_pika/tools.py", line 288, in wrapper
    return await result
           ^^^^^^^^^^^^
  File "/Users/damonguzman/Desktop/projects/turing_agents/scripts/coordinator.py", line 59, in _on_message
    token = context.attach(ctx)
            ^^^^^^^
NameError: name 'context' is not defined
Exception in callback _task_done(<Task finishe...not defined")>) at /Users/damonguzman/Desktop/projects/turing_agents/.venv/lib/python3.12/site-packages/aio_pika/tools.py:43
handle: <Handle _task_done(<Task finishe...not defined")>) at /Users/damonguzman/Desktop/projects/turing_agents/.venv/lib/python3.12/site-packages/aio_pika/tools.py:43>
Traceback (most recent call last):
  File "/Users/damonguzman/.local/share/uv/python/cpython-3.12.11-macos-aarch64-none/lib/python3.12/asyncio/events.py", line 88, in _run
    self._context.run(self._callback, *self._args)
  File "/Users/damonguzman/Desktop/projects/turing_agents/.venv/lib/python3.12/site-packages/aio_pika/tools.py", line 47, in _task_done
    raise exc
  File "/Users/damonguzman/Desktop/projects/turing_agents/.venv/lib/python3.12/site-packages/aio_pika/tools.py", line 288, in wrapper
    return await result
           ^^^^^^^^^^^^
  File "/Users/damonguzman/Desktop/projects/turing_agents/scripts/coordinator.py", line 59, in _on_message
    token = context.attach(ctx)
            ^^^^^^^
NameError: name 'context' is not defined
Task exception was never retrieved
future: <Task finished name='Task-54' coro=<consumer() done, defined at /Users/damonguzman/Desktop/projects/turing_agents/.venv/lib/python3.12/site-packages/aio_pika/queue.py:31> exception=NameError("name 'context' is not defined")>
Traceback (most recent call last):
  File "/Users/damonguzman/Desktop/projects/turing_agents/.venv/lib/python3.12/site-packages/aio_pika/queue.py", line 37, in consumer
    return await create_task(callback, message)
           ^^^^^^^^^^^^^^^^^^^^^^^^^^^^^^^^^^^^
  File "/Users/damonguzman/Desktop/projects/turing_agents/.venv/lib/python3.12/site-packages/aio_pika/tools.py", line 288, in wrapper
    return await result
           ^^^^^^^^^^^^
  File "/Users/damonguzman/Desktop/projects/turing_agents/scripts/coordinator.py", line 59, in _on_message
    token = context.attach(ctx)
            ^^^^^^^
NameError: name 'context' is not defined
Exception in callback _task_done(<Task finishe...not defined")>) at /Users/damonguzman/Desktop/projects/turing_agents/.venv/lib/python3.12/site-packages/aio_pika/tools.py:43
handle: <Handle _task_done(<Task finishe...not defined")>) at /Users/damonguzman/Desktop/projects/turing_agents/.venv/lib/python3.12/site-packages/aio_pika/tools.py:43>
Traceback (most recent call last):
  File "/Users/damonguzman/.local/share/uv/python/cpython-3.12.11-macos-aarch64-none/lib/python3.12/asyncio/events.py", line 88, in _run
    self._context.run(self._callback, *self._args)
  File "/Users/damonguzman/Desktop/projects/turing_agents/.venv/lib/python3.12/site-packages/aio_pika/tools.py", line 47, in _task_done
    raise exc
  File "/Users/damonguzman/Desktop/projects/turing_agents/.venv/lib/python3.12/site-packages/aio_pika/tools.py", line 288, in wrapper
    return await result
           ^^^^^^^^^^^^
  File "/Users/damonguzman/Desktop/projects/turing_agents/scripts/coordinator.py", line 59, in _on_message
    token = context.attach(ctx)
            ^^^^^^^
NameError: name 'context' is not defined
Task exception was never retrieved
future: <Task finished name='Task-56' coro=<consumer() done, defined at /Users/damonguzman/Desktop/projects/turing_agents/.venv/lib/python3.12/site-packages/aio_pika/queue.py:31> exception=NameError("name 'context' is not defined")>
Traceback (most recent call last):
  File "/Users/damonguzman/Desktop/projects/turing_agents/.venv/lib/python3.12/site-packages/aio_pika/queue.py", line 37, in consumer
    return await create_task(callback, message)
           ^^^^^^^^^^^^^^^^^^^^^^^^^^^^^^^^^^^^
  File "/Users/damonguzman/Desktop/projects/turing_agents/.venv/lib/python3.12/site-packages/aio_pika/tools.py", line 288, in wrapper
    return await result
           ^^^^^^^^^^^^
  File "/Users/damonguzman/Desktop/projects/turing_agents/scripts/coordinator.py", line 59, in _on_message
    token = context.attach(ctx)
            ^^^^^^^
NameError: name 'context' is not defined
Exception in callback _task_done(<Task finishe...not defined")>) at /Users/damonguzman/Desktop/projects/turing_agents/.venv/lib/python3.12/site-packages/aio_pika/tools.py:43
handle: <Handle _task_done(<Task finishe...not defined")>) at /Users/damonguzman/Desktop/projects/turing_agents/.venv/lib/python3.12/site-packages/aio_pika/tools.py:43>
Traceback (most recent call last):
  File "/Users/damonguzman/.local/share/uv/python/cpython-3.12.11-macos-aarch64-none/lib/python3.12/asyncio/events.py", line 88, in _run
    self._context.run(self._callback, *self._args)
  File "/Users/damonguzman/Desktop/projects/turing_agents/.venv/lib/python3.12/site-packages/aio_pika/tools.py", line 47, in _task_done
    raise exc
  File "/Users/damonguzman/Desktop/projects/turing_agents/.venv/lib/python3.12/site-packages/aio_pika/tools.py", line 288, in wrapper
    return await result
           ^^^^^^^^^^^^
  File "/Users/damonguzman/Desktop/projects/turing_agents/scripts/coordinator.py", line 59, in _on_message
    token = context.attach(ctx)
            ^^^^^^^
NameError: name 'context' is not defined
Task exception was never retrieved
future: <Task finished name='Task-58' coro=<consumer() done, defined at /Users/damonguzman/Desktop/projects/turing_agents/.venv/lib/python3.12/site-packages/aio_pika/queue.py:31> exception=NameError("name 'context' is not defined")>
Traceback (most recent call last):
  File "/Users/damonguzman/Desktop/projects/turing_agents/.venv/lib/python3.12/site-packages/aio_pika/queue.py", line 37, in consumer
    return await create_task(callback, message)
           ^^^^^^^^^^^^^^^^^^^^^^^^^^^^^^^^^^^^
  File "/Users/damonguzman/Desktop/projects/turing_agents/.venv/lib/python3.12/site-packages/aio_pika/tools.py", line 288, in wrapper
    return await result
           ^^^^^^^^^^^^
  File "/Users/damonguzman/Desktop/projects/turing_agents/scripts/coordinator.py", line 59, in _on_message
    token = context.attach(ctx)
            ^^^^^^^
NameError: name 'context' is not defined
Exception in callback _task_done(<Task finishe...not defined")>) at /Users/damonguzman/Desktop/projects/turing_agents/.venv/lib/python3.12/site-packages/aio_pika/tools.py:43
handle: <Handle _task_done(<Task finishe...not defined")>) at /Users/damonguzman/Desktop/projects/turing_agents/.venv/lib/python3.12/site-packages/aio_pika/tools.py:43>
Traceback (most recent call last):
  File "/Users/damonguzman/.local/share/uv/python/cpython-3.12.11-macos-aarch64-none/lib/python3.12/asyncio/events.py", line 88, in _run
    self._context.run(self._callback, *self._args)
  File "/Users/damonguzman/Desktop/projects/turing_agents/.venv/lib/python3.12/site-packages/aio_pika/tools.py", line 47, in _task_done
    raise exc
  File "/Users/damonguzman/Desktop/projects/turing_agents/.venv/lib/python3.12/site-packages/aio_pika/tools.py", line 288, in wrapper
    return await result
           ^^^^^^^^^^^^
  File "/Users/damonguzman/Desktop/projects/turing_agents/scripts/coordinator.py", line 59, in _on_message
    token = context.attach(ctx)
            ^^^^^^^
NameError: name 'context' is not defined
Task exception was never retrieved
future: <Task finished name='Task-60' coro=<consumer() done, defined at /Users/damonguzman/Desktop/projects/turing_agents/.venv/lib/python3.12/site-packages/aio_pika/queue.py:31> exception=NameError("name 'context' is not defined")>
Traceback (most recent call last):
  File "/Users/damonguzman/Desktop/projects/turing_agents/.venv/lib/python3.12/site-packages/aio_pika/queue.py", line 37, in consumer
    return await create_task(callback, message)
           ^^^^^^^^^^^^^^^^^^^^^^^^^^^^^^^^^^^^
  File "/Users/damonguzman/Desktop/projects/turing_agents/.venv/lib/python3.12/site-packages/aio_pika/tools.py", line 288, in wrapper
    return await result
           ^^^^^^^^^^^^
  File "/Users/damonguzman/Desktop/projects/turing_agents/scripts/coordinator.py", line 59, in _on_message
    token = context.attach(ctx)
            ^^^^^^^
NameError: name 'context' is not defined
Exception in callback _task_done(<Task finishe...not defined")>) at /Users/damonguzman/Desktop/projects/turing_agents/.venv/lib/python3.12/site-packages/aio_pika/tools.py:43
handle: <Handle _task_done(<Task finishe...not defined")>) at /Users/damonguzman/Desktop/projects/turing_agents/.venv/lib/python3.12/site-packages/aio_pika/tools.py:43>
Traceback (most recent call last):
  File "/Users/damonguzman/.local/share/uv/python/cpython-3.12.11-macos-aarch64-none/lib/python3.12/asyncio/events.py", line 88, in _run
    self._context.run(self._callback, *self._args)
  File "/Users/damonguzman/Desktop/projects/turing_agents/.venv/lib/python3.12/site-packages/aio_pika/tools.py", line 47, in _task_done
    raise exc
  File "/Users/damonguzman/Desktop/projects/turing_agents/.venv/lib/python3.12/site-packages/aio_pika/tools.py", line 288, in wrapper
    return await result
           ^^^^^^^^^^^^
  File "/Users/damonguzman/Desktop/projects/turing_agents/scripts/coordinator.py", line 59, in _on_message
    token = context.attach(ctx)
            ^^^^^^^
NameError: name 'context' is not defined
Task exception was never retrieved
future: <Task finished name='Task-62' coro=<consumer() done, defined at /Users/damonguzman/Desktop/projects/turing_agents/.venv/lib/python3.12/site-packages/aio_pika/queue.py:31> exception=NameError("name 'context' is not defined")>
Traceback (most recent call last):
  File "/Users/damonguzman/Desktop/projects/turing_agents/.venv/lib/python3.12/site-packages/aio_pika/queue.py", line 37, in consumer
    return await create_task(callback, message)
           ^^^^^^^^^^^^^^^^^^^^^^^^^^^^^^^^^^^^
  File "/Users/damonguzman/Desktop/projects/turing_agents/.venv/lib/python3.12/site-packages/aio_pika/tools.py", line 288, in wrapper
    return await result
           ^^^^^^^^^^^^
  File "/Users/damonguzman/Desktop/projects/turing_agents/scripts/coordinator.py", line 59, in _on_message
    token = context.attach(ctx)
            ^^^^^^^
NameError: name 'context' is not defined
Exception in callback _task_done(<Task finishe...not defined")>) at /Users/damonguzman/Desktop/projects/turing_agents/.venv/lib/python3.12/site-packages/aio_pika/tools.py:43
handle: <Handle _task_done(<Task finishe...not defined")>) at /Users/damonguzman/Desktop/projects/turing_agents/.venv/lib/python3.12/site-packages/aio_pika/tools.py:43>
Traceback (most recent call last):
  File "/Users/damonguzman/.local/share/uv/python/cpython-3.12.11-macos-aarch64-none/lib/python3.12/asyncio/events.py", line 88, in _run
    self._context.run(self._callback, *self._args)
  File "/Users/damonguzman/Desktop/projects/turing_agents/.venv/lib/python3.12/site-packages/aio_pika/tools.py", line 47, in _task_done
    raise exc
  File "/Users/damonguzman/Desktop/projects/turing_agents/.venv/lib/python3.12/site-packages/aio_pika/tools.py", line 288, in wrapper
    return await result
           ^^^^^^^^^^^^
  File "/Users/damonguzman/Desktop/projects/turing_agents/scripts/coordinator.py", line 59, in _on_message
    token = context.attach(ctx)
            ^^^^^^^
NameError: name 'context' is not defined
Task exception was never retrieved
future: <Task finished name='Task-64' coro=<consumer() done, defined at /Users/damonguzman/Desktop/projects/turing_agents/.venv/lib/python3.12/site-packages/aio_pika/queue.py:31> exception=NameError("name 'context' is not defined")>
Traceback (most recent call last):
  File "/Users/damonguzman/Desktop/projects/turing_agents/.venv/lib/python3.12/site-packages/aio_pika/queue.py", line 37, in consumer
    return await create_task(callback, message)
           ^^^^^^^^^^^^^^^^^^^^^^^^^^^^^^^^^^^^
  File "/Users/damonguzman/Desktop/projects/turing_agents/.venv/lib/python3.12/site-packages/aio_pika/tools.py", line 288, in wrapper
    return await result
           ^^^^^^^^^^^^
  File "/Users/damonguzman/Desktop/projects/turing_agents/scripts/coordinator.py", line 59, in _on_message
    token = context.attach(ctx)
            ^^^^^^^
NameError: name 'context' is not defined
timestamp": "2025-08-22T06:33:12Z"}
Coordinator routed response for demo-agent: 08b434c2-79a6-4888-bee8-010b7e7fdeb0
[demo-agent response] {"request_id": "08b434c2-79a6-4888-bee8-010b7e7fdeb0", "type": "result", "result": {"echo": {}}, "timestamp": "2025-08-22T06:33:42Z"}
Coordinator routed response for demo-agent: 4064de46-01c3-4c2c-9c90-390ab51be56f
[demo-agent response] {"request_id": "4064de46-01c3-4c2c-9c90-390ab51be56f", "type": "result", "result": {"echo": {}}, "timestamp": "2025-08-22T06:33:42Z"}
Coordinator routed response for demo-agent: a79cccab-77d5-4668-9576-c355596cab16
[demo-agent response] {"request_id": "a79cccab-77d5-4668-9576-c355596cab16", "type": "result", "result": {"echo": {}}, "timestamp": "2025-08-22T06:33:42Z"}
Coordinator routed response for demo-agent: 2572f79c-f9e7-4a13-afda-a61c01215281
[demo-agent response] {"request_id": "2572f79c-f9e7-4a13-afda-a61c01215281", "type": "result", "result": {"echo": {}}, "timestamp": "2025-08-22T06:33:42Z"}
Coordinator routed response for demo-agent: f2f0d6ae-4cc2-453f-9727-7cad4b20b16f
[demo-agent response] {"request_id": "f2f0d6ae-4cc2-453f-9727-7cad4b20b16f", "type": "result", "result": {"echo": {}}, "timestamp": "2025-08-22T06:33:42Z"}
Coordinator routed response for demo-agent: d8ae3c49-3a43-46bf-afac-3f934a9c4e8a
[demo-agent response] {"request_id": "d8ae3c49-3a43-46bf-afac-3f934a9c4e8a", "type": "result", "result": {"echo": {}}, "timestamp": "2025-08-22T06:33:42Z"}
Coordinator routed response for demo-agent: f3083fbb-2105-49b2-b4c3-86079ef4cacf
[demo-agent response] {"request_id": "f3083fbb-2105-49b2-b4c3-86079ef4cacf", "type": "result", "result": {"echo": {}}, "timestamp": "2025-08-22T06:33:42Z"}
Coordinator routed response for demo-agent: 5e5271b4-1a56-4c53-924e-223a583dc5d6
[demo-agent response] {"request_id": "5e5271b4-1a56-4c53-924e-223a583dc5d6", "type": "result", "result": {"echo": {}}, "timestamp": "2025-08-22T06:33:42Z"}
Coordinator routed response for demo-agent: c4e94c6d-8c33-43cc-8960-026240ef30f1
[demo-agent response] {"request_id": "c4e94c6d-8c33-43cc-8960-026240ef30f1", "type": "result", "result": {"echo": {}}, "timestamp": "2025-08-22T06:33:42Z"}
Coordinator routed response for demo-agent: 07276c3e-8205-4f9b-bf16-25602246851e
[demo-agent response] {"request_id": "07276c3e-8205-4f9b-bf16-25602246851e", "type": "result", "result": {"echo": {}}, "timestamp": "2025-08-22T06:33:42Z"}
Coordinator routed response for demo-agent: 9927b77c-6645-4ac8-95a1-b539fda63283
[demo-agent response] {"request_id": "9927b77c-6645-4ac8-95a1-b539fda63283", "type": "result", "result": {"echo": {}}, "timestamp": "2025-08-22T06:33:42Z"}
Coordinator routed response for demo-agent: d6cd1936-976e-42ca-a5c0-e3f166b7a591
[demo-agent response] {"request_id": "d6cd1936-976e-42ca-a5c0-e3f166b7a591", "type": "result", "result": {"echo": {}}, "timestamp": "2025-08-22T06:33:42Z"}
Coordinator routed response for demo-agent: 05752824-8c3b-4fcd-9d5b-a7979b7763e1
[demo-agent response] {"request_id": "05752824-8c3b-4fcd-9d5b-a7979b7763e1", "type": "result", "result": {"echo": {}}, "timestamp": "2025-08-22T06:33:42Z"}
Coordinator routed response for demo-agent: eddde5c3-bc4a-453e-872c-3435841e62a4
[demo-agent response] {"request_id": "eddde5c3-bc4a-453e-872c-3435841e62a4", "type": "result", "result": {"echo": {}}, "timestamp": "2025-08-22T06:33:42Z"}
Coordinator routed response for demo-agent: 9bab78e7-8247-418e-bc44-b3a4c3b6e421
[demo-agent response] {"request_id": "9bab78e7-8247-418e-bc44-b3a4c3b6e421", "type": "result", "result": {"echo": {}}, "timestamp": "2025-08-22T06:33:42Z"}
Coordinator routed response for demo-agent: 469bfd19-d177-41dc-b8b1-a5a37f6d758b
[demo-agent response] {"request_id": "469bfd19-d177-41dc-b8b1-a5a37f6d758b", "type": "result", "result": {"echo": {}}, "timestamp": "2025-08-22T06:33:42Z"}
Coordinator routed response for demo-agent: 4b636e55-48bf-46ae-bb76-ec783a52ece6
[demo-agent response] {"request_id": "4b636e55-48bf-46ae-bb76-ec783a52ece6", "type": "result", "result": {"echo": {}}, "timestamp": "2025-08-22T06:33:42Z"}
Coordinator routed response for demo-agent: 451245ac-26ab-448b-932e-994ff97b273b
[demo-agent response] {"request_id": "451245ac-26ab-448b-932e-994ff97b273b", "type": "result", "result": {"echo": {}}, "timestamp": "2025-08-22T06:33:42Z"}
Coordinator routed response for demo-agent: 9c22d95b-8da8-4f6b-98e1-dec1299553c1
[demo-agent response] {"request_id": "9c22d95b-8da8-4f6b-98e1-dec1299553c1", "type": "result", "result": {"echo": {}}, "timestamp": "2025-08-22T06:33:42Z"}
Coordinator routed response for demo-agent: fff6c83d-7b00-4375-ab55-fe22ac26c0b3
[demo-agent response] {"request_id": "fff6c83d-7b00-4375-ab55-fe22ac26c0b3", "type": "result", "result": {"echo": {}}, "timestamp": "2025-08-22T06:33:42Z"}
Coordinator routed response for demo-agent: 38471e39-d2ea-45b7-a1b2-5e7981ca108c
[demo-agent response] {"request_id": "38471e39-d2ea-45b7-a1b2-5e7981ca108c", "type": "result", "result": {"echo": {}}, "timestamp": "2025-08-22T06:33:42Z"}
Coordinator routed response for demo-agent: 23f1bb82-8a5b-4927-81ae-0193ee08c55d
[demo-agent response] {"request_id": "23f1bb82-8a5b-4927-81ae-0193ee08c55d", "type": "result", "result": {"echo": {}}, "timestamp": "2025-08-22T06:33:42Z"}
Coordinator routed response for demo-agent: 717412fd-3255-4371-9d9b-31ccaf708f96
[demo-agent response] {"request_id": "717412fd-3255-4371-9d9b-31ccaf708f96", "type": "result", "result": {"echo": {}}, "timestamp": "2025-08-22T06:33:42Z"}
Coordinator routed response for demo-agent: 04bc13a5-7c9a-42e9-a8ce-938f597c41d7
[demo-agent response] {"request_id": "04bc13a5-7c9a-42e9-a8ce-938f597c41d7", "type": "result", "result": {"echo": {}}, "timestamp": "2025-08-22T06:33:42Z"}
Coordinator routed response for demo-agent: b4263e01-b6af-4f04-a7e0-3a7904ddc562
[demo-agent response] {"request_id": "b4263e01-b6af-4f04-a7e0-3a7904ddc562", "type": "result", "result": {"echo": {}}, "timestamp": "2025-08-22T06:33:42Z"}
